Workbook

Sheet LENGUA ESPAÑOLA
A1: Numero | B1: Nombre/Apellido | C1: Docente: Años Escolar: 2025-2026 Grado: Centro Educativo: Jose Bordas Valdez | E1: =Datos!D2 | AD1: Final de área
C2: Años Escolar: | F2: =Datos!D4
C3: Grado: | E3: =Datos!D6
C4: Centro Educativo: | G4: =Datos!D8
C5: C1. comunicatica | K5: C2. Pensamiento Lógico, Creativo y Crítico | S5: C3. Ética y Ciudadana | AA5: Promedio del área por C.
C7: P1 | D7: R1 | E7: P2 | F7: R2 | G7: P3 | H7: R3 | I7: P4 | J7: R4 | K7: P1 | L7: R1 | M7: P2 | N7: R2 | O7: P3 | P7: R3 | Q7: P4 | R7: R4 | S7: P1 | T7: R1 | U7: P2 | V7: R2 | W7: P3 | X7: R3 | Y7: P4 | Z7: R4 | AA7: C1 | AB7: C2 | AC7: C3
A8: 1 | B8: Erick Moreta | AA8: =IF( OR( C8="", E8="", G8="", I8="", AND(C8<=64, D8=""), AND(E8<=64, F8=""), AND(G8<=64, H8=""), AND(I8<=64, J8="") ), "", AVERAGE( IF(C8<=64, D8, C8), IF(E8<=64, F8, E8), IF(G8<=64, H8, G8), IF(I8<=64, J8, I8) ) ) | AB8: =IF( OR( K8="", M8="", O8="", Q8="", AND(K8<=64, L8=""), AND(M8<=64, N8=""), AND(O8<=64, P8=""), AND(Q8<=64, R8="") ), "", AVERAGE( IF(K8<=64, L8, K8), IF(M8<=64, N8, M8), IF(O8<=64, P8, O8), IF(Q8<=64, R8, Q8) ) ) | AC8: =IF( OR( S8="", U8="", W8="", Y8="", AND(S8<=64, T8=""), AND(U8<=64, V8=""), AND(W8<=64, X8=""), AND(Y8<=64, Z8="") ), "", AVERAGE( IF(S8<=64, T8, S8), IF(U8<=64, V8, U8), IF(W8<=64, X8, W8), IF(Y8<=64, Z8, Y8) ) ) | AD8: =IF(COUNT(AA8, AB8, AC8)<3, "", AVERAGE(AA8, AB8, AC8))
A9: 2 | B9: =Datos!B3 | AA9: =IF( OR( C9="", E9="", G9="", I9="", AND(C9<=64, D9=""), AND(E9<=64, F9=""), AND(G9<=64, H9=""), AND(I9<=64, J9="") ), "", AVERAGE( IF(C9<=64, D9, C9), IF(E9<=64, F9, E9), IF(G9<=64, H9, G9), IF(I9<=64, J9, I9) ) ) | AB9: =IF( OR( D9="", F9="", H9="", J9="", AND(D9<=64, E9=""), AND(F9<=64, G9=""), AND(H9<=64, I9=""), AND(J9<=64, K9="") ), "", AVERAGE( IF(D9<=64, E9, D9), IF(F9<=64, G9, F9), IF(H9<=64, I9, H9), IF(J9<=64, K9, J9) ) ) | AC9: =IF( OR( E9="", G9="", I9="", K9="", AND(E9<=64, F9=""), AND(G9<=64, H9=""), AND(I9<=64, J9=""), AND(K9<=64, L9="") ), "", AVERAGE( IF(E9<=64, F9, E9), IF(G9<=64, H9, G9), IF(I9<=64, J9, I9), IF(K9<=64, L9, K9) ) ) | AD9: =IF(COUNT(AA9, AB9, AC9)<3, "", AVERAGE(AA9, AB9, AC9))
A10: 3 | B10: =Datos!B4 | AA10: =IF( OR( C10="", E10="", G10="", I10="", AND(C10<=64, D10=""), AND(E10<=64, F10=""), AND(G10<=64, H10=""), AND(I10<=64, J10="") ), "", AVERAGE( IF(C10<=64, D10, C10), IF(E10<=64, F10, E10), IF(G10<=64, H10, G10), IF(I10<=64, J10, I10) ) ) | AB10: =IF( OR( D10="", F10="", H10="", J10="", AND(D10<=64, E10=""), AND(F10<=64, G10=""), AND(H10<=64, I10=""), AND(J10<=64, K10="") ), "", AVERAGE( IF(D10<=64, E10, D10), IF(F10<=64, G10, F10), IF(H10<=64, I10, H10), IF(J10<=64, K10, J10) ) ) | AC10: =IF( OR( E10="", G10="", I10="", K10="", AND(E10<=64, F10=""), AND(G10<=64, H10=""), AND(I10<=64, J10=""), AND(K10<=64, L10="") ), "", AVERAGE( IF(E10<=64, F10, E10), IF(G10<=64, H10, G10), IF(I10<=64, J10, I10), IF(K10<=64, L10, K10) ) ) | AD10: =IF(COUNT(AA10, AB10, AC10)<3, "", AVERAGE(AA10, AB10, AC10))
A11: 4 | B11: =Datos!B5 | AA11: =IF( OR( C11="", E11="", G11="", I11="", AND(C11<=64, D11=""), AND(E11<=64, F11=""), AND(G11<=64, H11=""), AND(I11<=64, J11="") ), "", AVERAGE( IF(C11<=64, D11, C11), IF(E11<=64, F11, E11), IF(G11<=64, H11, G11), IF(I11<=64, J11, I11) ) ) | AB11: =IF( OR( D11="", F11="", H11="", J11="", AND(D11<=64, E11=""), AND(F11<=64, G11=""), AND(H11<=64, I11=""), AND(J11<=64, K11="") ), "", AVERAGE( IF(D11<=64, E11, D11), IF(F11<=64, G11, F11), IF(H11<=64, I11, H11), IF(J11<=64, K11, J11) ) ) | AC11: =IF( OR( E11="", G11="", I11="", K11="", AND(E11<=64, F11=""), AND(G11<=64, H11=""), AND(I11<=64, J11=""), AND(K11<=64, L11="") ), "", AVERAGE( IF(E11<=64, F11, E11), IF(G11<=64, H11, G11), IF(I11<=64, J11, I11), IF(K11<=64, L11, K11) ) ) | AD11: =IF(COUNT(AA11, AB11, AC11)<3, "", AVERAGE(AA11, AB11, AC11))
A12: 5 | B12: =Datos!B6 | AA12: =IF( OR( C12="", E12="", G12="", I12="", AND(C12<=64, D12=""), AND(E12<=64, F12=""), AND(G12<=64, H12=""), AND(I12<=64, J12="") ), "", AVERAGE( IF(C12<=64, D12, C12), IF(E12<=64, F12, E12), IF(G12<=64, H12, G12), IF(I12<=64, J12, I12) ) ) | AB12: =IF( OR( D12="", F12="", H12="", J12="", AND(D12<=64, E12=""), AND(F12<=64, G12=""), AND(H12<=64, I12=""), AND(J12<=64, K12="") ), "", AVERAGE( IF(D12<=64, E12, D12), IF(F12<=64, G12, F12), IF(H12<=64, I12, H12), IF(J12<=64, K12, J12) ) ) | AC12: =IF( OR( E12="", G12="", I12="", K12="", AND(E12<=64, F12=""), AND(G12<=64, H12=""), AND(I12<=64, J12=""), AND(K12<=64, L12="") ), "", AVERAGE( IF(E12<=64, F12, E12), IF(G12<=64, H12, G12), IF(I12<=64, J12, I12), IF(K12<=64, L12, K12) ) ) | AD12: =IF(COUNT(AA12, AB12, AC12)<3, "", AVERAGE(AA12, AB12, AC12))
A13: 6 | B13: =Datos!B7 | AA13: =IF( OR( C13="", E13="", G13="", I13="", AND(C13<=64, D13=""), AND(E13<=64, F13=""), AND(G13<=64, H13=""), AND(I13<=64, J13="") ), "", AVERAGE( IF(C13<=64, D13, C13), IF(E13<=64, F13, E13), IF(G13<=64, H13, G13), IF(I13<=64, J13, I13) ) ) | AB13: =IF( OR( D13="", F13="", H13="", J13="", AND(D13<=64, E13=""), AND(F13<=64, G13=""), AND(H13<=64, I13=""), AND(J13<=64, K13="") ), "", AVERAGE( IF(D13<=64, E13, D13), IF(F13<=64, G13, F13), IF(H13<=64, I13, H13), IF(J13<=64, K13, J13) ) ) | AC13: =IF( OR( E13="", G13="", I13="", K13="", AND(E13<=64, F13=""), AND(G13<=64, H13=""), AND(I13<=64, J13=""), AND(K13<=64, L13="") ), "", AVERAGE( IF(E13<=64, F13, E13), IF(G13<=64, H13, G13), IF(I13<=64, J13, I13), IF(K13<=64, L13, K13) ) ) | AD13: =IF(COUNT(AA13, AB13, AC13)<3, "", AVERAGE(AA13, AB13, AC13))
A14: 7 | B14: =Datos!B8 | AA14: =IF( OR( C14="", E14="", G14="", I14="", AND(C14<=64, D14=""), AND(E14<=64, F14=""), AND(G14<=64, H14=""), AND(I14<=64, J14="") ), "", AVERAGE( IF(C14<=64, D14, C14), IF(E14<=64, F14, E14), IF(G14<=64, H14, G14), IF(I14<=64, J14, I14) ) ) | AB14: =IF( OR( D14="", F14="", H14="", J14="", AND(D14<=64, E14=""), AND(F14<=64, G14=""), AND(H14<=64, I14=""), AND(J14<=64, K14="") ), "", AVERAGE( IF(D14<=64, E14, D14), IF(F14<=64, G14, F14), IF(H14<=64, I14, H14), IF(J14<=64, K14, J14) ) ) | AC14: =IF( OR( E14="", G14="", I14="", K14="", AND(E14<=64, F14=""), AND(G14<=64, H14=""), AND(I14<=64, J14=""), AND(K14<=64, L14="") ), "", AVERAGE( IF(E14<=64, F14, E14), IF(G14<=64, H14, G14), IF(I14<=64, J14, I14), IF(K14<=64, L14, K14) ) ) | AD14: =IF(COUNT(AA14, AB14, AC14)<3, "", AVERAGE(AA14, AB14, AC14))
A15: 8 | B15: =Datos!B9 | AA15: =IF( OR( C15="", E15="", G15="", I15="", AND(C15<=64, D15=""), AND(E15<=64, F15=""), AND(G15<=64, H15=""), AND(I15<=64, J15="") ), "", AVERAGE( IF(C15<=64, D15, C15), IF(E15<=64, F15, E15), IF(G15<=64, H15, G15), IF(I15<=64, J15, I15) ) ) | AB15: =IF( OR( D15="", F15="", H15="", J15="", AND(D15<=64, E15=""), AND(F15<=64, G15=""), AND(H15<=64, I15=""), AND(J15<=64, K15="") ), "", AVERAGE( IF(D15<=64, E15, D15), IF(F15<=64, G15, F15), IF(H15<=64, I15, H15), IF(J15<=64, K15, J15) ) ) | AC15: =IF( OR( E15="", G15="", I15="", K15="", AND(E15<=64, F15=""), AND(G15<=64, H15=""), AND(I15<=64, J15=""), AND(K15<=64, L15="") ), "", AVERAGE( IF(E15<=64, F15, E15), IF(G15<=64, H15, G15), IF(I15<=64, J15, I15), IF(K15<=64, L15, K15) ) ) | AD15: =IF(COUNT(AA15, AB15, AC15)<3, "", AVERAGE(AA15, AB15, AC15))
A16: 9 | B16: =Datos!B10 | AA16: =IF( OR( C16="", E16="", G16="", I16="", AND(C16<=64, D16=""), AND(E16<=64, F16=""), AND(G16<=64, H16=""), AND(I16<=64, J16="") ), "", AVERAGE( IF(C16<=64, D16, C16), IF(E16<=64, F16, E16), IF(G16<=64, H16, G16), IF(I16<=64, J16, I16) ) ) | AB16: =IF( OR( D16="", F16="", H16="", J16="", AND(D16<=64, E16=""), AND(F16<=64, G16=""), AND(H16<=64, I16=""), AND(J16<=64, K16="") ), "", AVERAGE( IF(D16<=64, E16, D16), IF(F16<=64, G16, F16), IF(H16<=64, I16, H16), IF(J16<=64, K16, J16) ) ) | AC16: =IF( OR( E16="", G16="", I16="", K16="", AND(E16<=64, F16=""), AND(G16<=64, H16=""), AND(I16<=64, J16=""), AND(K16<=64, L16="") ), "", AVERAGE( IF(E16<=64, F16, E16), IF(G16<=64, H16, G16), IF(I16<=64, J16, I16), IF(K16<=64, L16, K16) ) ) | AD16: =IF(COUNT(AA16, AB16, AC16)<3, "", AVERAGE(AA16, AB16, AC16))
A17: 10 | B17: =Datos!B11 | AA17: =IF( OR( C17="", E17="", G17="", I17="", AND(C17<=64, D17=""), AND(E17<=64, F17=""), AND(G17<=64, H17=""), AND(I17<=64, J17="") ), "", AVERAGE( IF(C17<=64, D17, C17), IF(E17<=64, F17, E17), IF(G17<=64, H17, G17), IF(I17<=64, J17, I17) ) ) | AB17: =IF( OR( D17="", F17="", H17="", J17="", AND(D17<=64, E17=""), AND(F17<=64, G17=""), AND(H17<=64, I17=""), AND(J17<=64, K17="") ), "", AVERAGE( IF(D17<=64, E17, D17), IF(F17<=64, G17, F17), IF(H17<=64, I17, H17), IF(J17<=64, K17, J17) ) ) | AC17: =IF( OR( E17="", G17="", I17="", K17="", AND(E17<=64, F17=""), AND(G17<=64, H17=""), AND(I17<=64, J17=""), AND(K17<=64, L17="") ), "", AVERAGE( IF(E17<=64, F17, E17), IF(G17<=64, H17, G17), IF(I17<=64, J17, I17), IF(K17<=64, L17, K17) ) ) | AD17: =IF(COUNT(AA17, AB17, AC17)<3, "", AVERAGE(AA17, AB17, AC17))
A18: 11 | B18: =Datos!B12 | AA18: =IF( OR( C18="", E18="", G18="", I18="", AND(C18<=64, D18=""), AND(E18<=64, F18=""), AND(G18<=64, H18=""), AND(I18<=64, J18="") ), "", AVERAGE( IF(C18<=64, D18, C18), IF(E18<=64, F18, E18), IF(G18<=64, H18, G18), IF(I18<=64, J18, I18) ) ) | AB18: =IF( OR( D18="", F18="", H18="", J18="", AND(D18<=64, E18=""), AND(F18<=64, G18=""), AND(H18<=64, I18=""), AND(J18<=64, K18="") ), "", AVERAGE( IF(D18<=64, E18, D18), IF(F18<=64, G18, F18), IF(H18<=64, I18, H18), IF(J18<=64, K18, J18) ) ) | AC18: =IF( OR( E18="", G18="", I18="", K18="", AND(E18<=64, F18=""), AND(G18<=64, H18=""), AND(I18<=64, J18=""), AND(K18<=64, L18="") ), "", AVERAGE( IF(E18<=64, F18, E18), IF(G18<=64, H18, G18), IF(I18<=64, J18, I18), IF(K18<=64, L18, K18) ) ) | AD18: =IF(COUNT(AA18, AB18, AC18)<3, "", AVERAGE(AA18, AB18, AC18))
A19: 12 | B19: =Datos!B13 | AA19: =IF( OR( C19="", E19="", G19="", I19="", AND(C19<=64, D19=""), AND(E19<=64, F19=""), AND(G19<=64, H19=""), AND(I19<=64, J19="") ), "", AVERAGE( IF(C19<=64, D19, C19), IF(E19<=64, F19, E19), IF(G19<=64, H19, G19), IF(I19<=64, J19, I19) ) ) | AB19: =IF( OR( D19="", F19="", H19="", J19="", AND(D19<=64, E19=""), AND(F19<=64, G19=""), AND(H19<=64, I19=""), AND(J19<=64, K19="") ), "", AVERAGE( IF(D19<=64, E19, D19), IF(F19<=64, G19, F19), IF(H19<=64, I19, H19), IF(J19<=64, K19, J19) ) ) | AC19: =IF( OR( E19="", G19="", I19="", K19="", AND(E19<=64, F19=""), AND(G19<=64, H19=""), AND(I19<=64, J19=""), AND(K19<=64, L19="") ), "", AVERAGE( IF(E19<=64, F19, E19), IF(G19<=64, H19, G19), IF(I19<=64, J19, I19), IF(K19<=64, L19, K19) ) ) | AD19: =IF(COUNT(AA19, AB19, AC19)<3, "", AVERAGE(AA19, AB19, AC19))
A20: 13 | B20: =Datos!B14 | AA20: =IF( OR( C20="", E20="", G20="", I20="", AND(C20<=64, D20=""), AND(E20<=64, F20=""), AND(G20<=64, H20=""), AND(I20<=64, J20="") ), "", AVERAGE( IF(C20<=64, D20, C20), IF(E20<=64, F20, E20), IF(G20<=64, H20, G20), IF(I20<=64, J20, I20) ) ) | AB20: =IF( OR( D20="", F20="", H20="", J20="", AND(D20<=64, E20=""), AND(F20<=64, G20=""), AND(H20<=64, I20=""), AND(J20<=64, K20="") ), "", AVERAGE( IF(D20<=64, E20, D20), IF(F20<=64, G20, F20), IF(H20<=64, I20, H20), IF(J20<=64, K20, J20) ) ) | AC20: =IF( OR( E20="", G20="", I20="", K20="", AND(E20<=64, F20=""), AND(G20<=64, H20=""), AND(I20<=64, J20=""), AND(K20<=64, L20="") ), "", AVERAGE( IF(E20<=64, F20, E20), IF(G20<=64, H20, G20), IF(I20<=64, J20, I20), IF(K20<=64, L20, K20) ) ) | AD20: =IF(COUNT(AA20, AB20, AC20)<3, "", AVERAGE(AA20, AB20, AC20))
... A42: 35 | B42: =Datos!B36 | AA42: =IF( OR( C42="", E42="", G42="", I42="", AND(C42<=64, D42=""), AND(E42<=64, F42=""), AND(G42<=64, H42=""), AND(I42<=64, J42="") ), "", AVERAGE( IF(C42<=64, D42, C42), IF(E42<=64, F42, E42), IF(G42<=64, H42, G42), IF(I42<=64, J42, I42) ) ) | AB42: =IF( OR( D42="", F42="", H42="", J42="", AND(D42<=64, E42=""), AND(F42<=64, G42=""), AND(H42<=64, I42=""), AND(J42<=64, K42="") ), "", AVERAGE( IF(D42<=64, E42, D42), IF(F42<=64, G42, F42), IF(H42<=64, I42, H42), IF(J42<=64, K42, J42) ) ) | AC42: =IF( OR( E42="", G42="", I42="", K42="", AND(E42<=64, F42=""), AND(G42<=64, H42=""), AND(I42<=64, J42=""), AND(K42<=64, L42="") ), "", AVERAGE( IF(E42<=64, F42, E42), IF(G42<=64, H42, G42), IF(I42<=64, J42, I42), IF(K42<=64, L42, K42) ) ) | AD42: =IF(COUNT(AA42, AB42, AC42)<3, "", AVERAGE(AA42, AB42, AC42))

Sheet MATEMÁTICA
A1: Numero | B1: Nombre/Apellido | C1: Docente: Años Escolar: 2025-2026 Grado: Centro Educativo: Jose Bordas Valdez | E1: =Datos!D2 | AD1: Final de área
C2: Años Escolar: | F2: =Datos!D4
C3: Grado: | E3: =Datos!D6
C4: Centro Educativo: | G4: =Datos!D8
C5: C1. comunicatica | K5: C2. Pensamiento Lógico, Creativo y Crítico | S5: C3. Ética y Ciudadana | AA5: Promedio del área por C.
C7: P1 | D7: R1 | E7: P2 | F7: R2 | G7: P3 | H7: R3 | I7: P4 | J7: R4 | K7: P1 | L7: R1 | M7: P2 | N7: R2 | O7: P3 | P7: R3 | Q7: P4 | R7: R4 | S7: P1 | T7: R1 | U7: P2 | V7: R2 | W7: P3 | X7: R3 | Y7: P4 | Z7: R4 | AA7: C1 | AB7: C2 | AC7: C3
A8: 1 | B8: =Datos!B2 | AA8: =IF( OR( C8="", E8="", G8="", I8="", AND(C8<=64, D8=""), AND(E8<=64, F8=""), AND(G8<=64, H8=""), AND(I8<=64, J8="") ), "", AVERAGE( IF(C8<=64, D8, C8), IF(E8<=64, F8, E8), IF(G8<=64, H8, G8), IF(I8<=64, J8, I8) ) ) | AB8: =IF( OR( K8="", M8="", O8="", Q8="", AND(K8<=64, L8=""), AND(M8<=64, N8=""), AND(O8<=64, P8=""), AND(Q8<=64, R8="") ), "", AVERAGE( IF(K8<=64, L8, K8), IF(M8<=64, N8, M8), IF(O8<=64, P8, O8), IF(Q8<=64, R8, Q8) ) ) | AC8: =IF( OR( S8="", U8="", W8="", Y8="", AND(S8<=64, T8=""), AND(U8<=64, V8=""), AND(W8<=64, X8=""), AND(Y8<=64, Z8="") ), "", AVERAGE( IF(S8<=64, T8, S8), IF(U8<=64, V8, U8), IF(W8<=64, X8, W8), IF(Y8<=64, Z8, Y8) ) ) | AD8: =IF(COUNT(AA8, AB8, AC8)<3, "", AVERAGE(AA8, AB8, AC8))
A9: 2 | B9: =Datos!B3 | AA9: =IF( OR( C9="", E9="", G9="", I9="", AND(C9<=64, D9=""), AND(E9<=64, F9=""), AND(G9<=64, H9=""), AND(I9<=64, J9="") ), "", AVERAGE( IF(C9<=64, D9, C9), IF(E9<=64, F9, E9), IF(G9<=64, H9, G9), IF(I9<=64, J9, I9) ) ) | AB9: =IF( OR( D9="", F9="", H9="", J9="", AND(D9<=64, E9=""), AND(F9<=64, G9=""), AND(H9<=64, I9=""), AND(J9<=64, K9="") ), "", AVERAGE( IF(D9<=64, E9, D9), IF(F9<=64, G9, F9), IF(H9<=64, I9, H9), IF(J9<=64, K9, J9) ) ) | AC9: =IF( OR( E9="", G9="", I9="", K9="", AND(E9<=64, F9=""), AND(G9<=64, H9=""), AND(I9<=64, J9=""), AND(K9<=64, L9="") ), "", AVERAGE( IF(E9<=64, F9, E9), IF(G9<=64, H9, G9), IF(I9<=64, J9, I9), IF(K9<=64, L9, K9) ) ) | AD9: =IF(COUNT(AA9, AB9, AC9)<3, "", AVERAGE(AA9, AB9, AC9))
A10: 3 | B10: =Datos!B4 | AA10: =IF( OR( C10="", E10="", G10="", I10="", AND(C10<=64, D10=""), AND(E10<=64, F10=""), AND(G10<=64, H10=""), AND(I10<=64, J10="") ), "", AVERAGE( IF(C10<=64, D10, C10), IF(E10<=64, F10, E10), IF(G10<=64, H10, G10), IF(I10<=64, J10, I10) ) ) | AB10: =IF( OR( D10="", F10="", H10="", J10="", AND(D10<=64, E10=""), AND(F10<=64, G10=""), AND(H10<=64, I10=""), AND(J10<=64, K10="") ), "", AVERAGE( IF(D10<=64, E10, D10), IF(F10<=64, G10, F10), IF(H10<=64, I10, H10), IF(J10<=64, K10, J10) ) ) | AC10: =IF( OR( E10="", G10="", I10="", K10="", AND(E10<=64, F10=""), AND(G10<=64, H10=""), AND(I10<=64, J10=""), AND(K10<=64, L10="") ), "", AVERAGE( IF(E10<=64, F10, E10), IF(G10<=64, H10, G10), IF(I10<=64, J10, I10), IF(K10<=64, L10, K10) ) ) | AD10: =IF(COUNT(AA10, AB10, AC10)<3, "", AVERAGE(AA10, AB10, AC10))
A11: 4 | B11: =Datos!B5 | AA11: =IF( OR( C11="", E11="", G11="", I11="", AND(C11<=64, D11=""), AND(E11<=64, F11=""), AND(G11<=64, H11=""), AND(I11<=64, J11="") ), "", AVERAGE( IF(C11<=64, D11, C11), IF(E11<=64, F11, E11), IF(G11<=64, H11, G11), IF(I11<=64, J11, I11) ) ) | AB11: =IF( OR( D11="", F11="", H11="", J11="", AND(D11<=64, E11=""), AND(F11<=64, G11=""), AND(H11<=64, I11=""), AND(J11<=64, K11="") ), "", AVERAGE( IF(D11<=64, E11, D11), IF(F11<=64, G11, F11), IF(H11<=64, I11, H11), IF(J11<=64, K11, J11) ) ) | AC11: =IF( OR( E11="", G11="", I11="", K11="", AND(E11<=64, F11=""), AND(G11<=64, H11=""), AND(I11<=64, J11=""), AND(K11<=64, L11="") ), "", AVERAGE( IF(E11<=64, F11, E11), IF(G11<=64, H11, G11), IF(I11<=64, J11, I11), IF(K11<=64, L11, K11) ) ) | AD11: =IF(COUNT(AA11, AB11, AC11)<3, "", AVERAGE(AA11, AB11, AC11))
A12: 5 | B12: =Datos!B6 | AA12: =IF( OR( C12="", E12="", G12="", I12="", AND(C12<=64, D12=""), AND(E12<=64, F12=""), AND(G12<=64, H12=""), AND(I12<=64, J12="") ), "", AVERAGE( IF(C12<=64, D12, C12), IF(E12<=64, F12, E12), IF(G12<=64, H12, G12), IF(I12<=64, J12, I12) ) ) | AB12: =IF( OR( D12="", F12="", H12="", J12="", AND(D12<=64, E12=""), AND(F12<=64, G12=""), AND(H12<=64, I12=""), AND(J12<=64, K12="") ), "", AVERAGE( IF(D12<=64, E12, D12), IF(F12<=64, G12, F12), IF(H12<=64, I12, H12), IF(J12<=64, K12, J12) ) ) | AC12: =IF( OR( E12="", G12="", I12="", K12="", AND(E12<=64, F12=""), AND(G12<=64, H12=""), AND(I12<=64, J12=""), AND(K12<=64, L12="") ), "", AVERAGE( IF(E12<=64, F12, E12), IF(G12<=64, H12, G12), IF(I12<=64, J12, I12), IF(K12<=64, L12, K12) ) ) | AD12: =IF(COUNT(AA12, AB12, AC12)<3, "", AVERAGE(AA12, AB12, AC12))
A13: 6 | B13: =Datos!B7 | AA13: =IF( OR( C13="", E13="", G13="", I13="", AND(C13<=64, D13=""), AND(E13<=64, F13=""), AND(G13<=64, H13=""), AND(I13<=64, J13="") ), "", AVERAGE( IF(C13<=64, D13, C13), IF(E13<=64, F13, E13), IF(G13<=64, H13, G13), IF(I13<=64, J13, I13) ) ) | AB13: =IF( OR( D13="", F13="", H13="", J13="", AND(D13<=64, E13=""), AND(F13<=64, G13=""), AND(H13<=64, I13=""), AND(J13<=64, K13="") ), "", AVERAGE( IF(D13<=64, E13, D13), IF(F13<=64, G13, F13), IF(H13<=64, I13, H13), IF(J13<=64, K13, J13) ) ) | AC13: =IF( OR( E13="", G13="", I13="", K13="", AND(E13<=64, F13=""), AND(G13<=64, H13=""), AND(I13<=64, J13=""), AND(K13<=64, L13="") ), "", AVERAGE( IF(E13<=64, F13, E13), IF(G13<=64, H13, G13), IF(I13<=64, J13, I13), IF(K13<=64, L13, K13) ) ) | AD13: =IF(COUNT(AA13, AB13, AC13)<3, "", AVERAGE(AA13, AB13, AC13))
A14: 7 | B14: =Datos!B8 | AA14: =IF( OR( C14="", E14="", G14="", I14="", AND(C14<=64, D14=""), AND(E14<=64, F14=""), AND(G14<=64, H14=""), AND(I14<=64, J14="") ), "", AVERAGE( IF(C14<=64, D14, C14), IF(E14<=64, F14, E14), IF(G14<=64, H14, G14), IF(I14<=64, J14, I14) ) ) | AB14: =IF( OR( D14="", F14="", H14="", J14="", AND(D14<=64, E14=""), AND(F14<=64, G14=""), AND(H14<=64, I14=""), AND(J14<=64, K14="") ), "", AVERAGE( IF(D14<=64, E14, D14), IF(F14<=64, G14, F14), IF(H14<=64, I14, H14), IF(J14<=64, K14, J14) ) ) | AC14: =IF( OR( E14="", G14="", I14="", K14="", AND(E14<=64, F14=""), AND(G14<=64, H14=""), AND(I14<=64, J14=""), AND(K14<=64, L14="") ), "", AVERAGE( IF(E14<=64, F14, E14), IF(G14<=64, H14, G14), IF(I14<=64, J14, I14), IF(K14<=64, L14, K14) ) ) | AD14: =IF(COUNT(AA14, AB14, AC14)<3, "", AVERAGE(AA14, AB14, AC14))
A15: 8 | B15: =Datos!B9 | AA15: =IF( OR( C15="", E15="", G15="", I15="", AND(C15<=64, D15=""), AND(E15<=64, F15=""), AND(G15<=64, H15=""), AND(I15<=64, J15="") ), "", AVERAGE( IF(C15<=64, D15, C15), IF(E15<=64, F15, E15), IF(G15<=64, H15, G15), IF(I15<=64, J15, I15) ) ) | AB15: =IF( OR( D15="", F15="", H15="", J15="", AND(D15<=64, E15=""), AND(F15<=64, G15=""), AND(H15<=64, I15=""), AND(J15<=64, K15="") ), "", AVERAGE( IF(D15<=64, E15, D15), IF(F15<=64, G15, F15), IF(H15<=64, I15, H15), IF(J15<=64, K15, J15) ) ) | AC15: =IF( OR( E15="", G15="", I15="", K15="", AND(E15<=64, F15=""), AND(G15<=64, H15=""), AND(I15<=64, J15=""), AND(K15<=64, L15="") ), "", AVERAGE( IF(E15<=64, F15, E15), IF(G15<=64, H15, G15), IF(I15<=64, J15, I15), IF(K15<=64, L15, K15) ) ) | AD15: =IF(COUNT(AA15, AB15, AC15)<3, "", AVERAGE(AA15, AB15, AC15))
A16: 9 | B16: =Datos!B10 | AA16: =IF( OR( C16="", E16="", G16="", I16="", AND(C16<=64, D16=""), AND(E16<=64, F16=""), AND(G16<=64, H16=""), AND(I16<=64, J16="") ), "", AVERAGE( IF(C16<=64, D16, C16), IF(E16<=64, F16, E16), IF(G16<=64, H16, G16), IF(I16<=64, J16, I16) ) ) | AB16: =IF( OR( D16="", F16="", H16="", J16="", AND(D16<=64, E16=""), AND(F16<=64, G16=""), AND(H16<=64, I16=""), AND(J16<=64, K16="") ), "", AVERAGE( IF(D16<=64, E16, D16), IF(F16<=64, G16, F16), IF(H16<=64, I16, H16), IF(J16<=64, K16, J16) ) ) | AC16: =IF( OR( E16="", G16="", I16="", K16="", AND(E16<=64, F16=""), AND(G16<=64, H16=""), AND(I16<=64, J16=""), AND(K16<=64, L16="") ), "", AVERAGE( IF(E16<=64, F16, E16), IF(G16<=64, H16, G16), IF(I16<=64, J16, I16), IF(K16<=64, L16, K16) ) ) | AD16: =IF(COUNT(AA16, AB16, AC16)<3, "", AVERAGE(AA16, AB16, AC16))
A17: 10 | B17: =Datos!B11 | AA17: =IF( OR( C17="", E17="", G17="", I17="", AND(C17<=64, D17=""), AND(E17<=64, F17=""), AND(G17<=64, H17=""), AND(I17<=64, J17="") ), "", AVERAGE( IF(C17<=64, D17, C17), IF(E17<=64, F17, E17), IF(G17<=64, H17, G17), IF(I17<=64, J17, I17) ) ) | AB17: =IF( OR( D17="", F17="", H17="", J17="", AND(D17<=64, E17=""), AND(F17<=64, G17=""), AND(H17<=64, I17=""), AND(J17<=64, K17="") ), "", AVERAGE( IF(D17<=64, E17, D17), IF(F17<=64, G17, F17), IF(H17<=64, I17, H17), IF(J17<=64, K17, J17) ) ) | AC17: =IF( OR( E17="", G17="", I17="", K17="", AND(E17<=64, F17=""), AND(G17<=64, H17=""), AND(I17<=64, J17=""), AND(K17<=64, L17="") ), "", AVERAGE( IF(E17<=64, F17, E17), IF(G17<=64, H17, G17), IF(I17<=64, J17, I17), IF(K17<=64, L17, K17) ) ) | AD17: =IF(COUNT(AA17, AB17, AC17)<3, "", AVERAGE(AA17, AB17, AC17))
A18: 11 | B18: =Datos!B12 | AA18: =IF( OR( C18="", E18="", G18="", I18="", AND(C18<=64, D18=""), AND(E18<=64, F18=""), AND(G18<=64, H18=""), AND(I18<=64, J18="") ), "", AVERAGE( IF(C18<=64, D18, C18), IF(E18<=64, F18, E18), IF(G18<=64, H18, G18), IF(I18<=64, J18, I18) ) ) | AB18: =IF( OR( D18="", F18="", H18="", J18="", AND(D18<=64, E18=""), AND(F18<=64, G18=""), AND(H18<=64, I18=""), AND(J18<=64, K18="") ), "", AVERAGE( IF(D18<=64, E18, D18), IF(F18<=64, G18, F18), IF(H18<=64, I18, H18), IF(J18<=64, K18, J18) ) ) | AC18: =IF( OR( E18="", G18="", I18="", K18="", AND(E18<=64, F18=""), AND(G18<=64, H18=""), AND(I18<=64, J18=""), AND(K18<=64, L18="") ), "", AVERAGE( IF(E18<=64, F18, E18), IF(G18<=64, H18, G18), IF(I18<=64, J18, I18), IF(K18<=64, L18, K18) ) ) | AD18: =IF(COUNT(AA18, AB18, AC18)<3, "", AVERAGE(AA18, AB18, AC18))
A19: 12 | B19: =Datos!B13 | AA19: =IF( OR( C19="", E19="", G19="", I19="", AND(C19<=64, D19=""), AND(E19<=64, F19=""), AND(G19<=64, H19=""), AND(I19<=64, J19="") ), "", AVERAGE( IF(C19<=64, D19, C19), IF(E19<=64, F19, E19), IF(G19<=64, H19, G19), IF(I19<=64, J19, I19) ) ) | AB19: =IF( OR( D19="", F19="", H19="", J19="", AND(D19<=64, E19=""), AND(F19<=64, G19=""), AND(H19<=64, I19=""), AND(J19<=64, K19="") ), "", AVERAGE( IF(D19<=64, E19, D19), IF(F19<=64, G19, F19), IF(H19<=64, I19, H19), IF(J19<=64, K19, J19) ) ) | AC19: =IF( OR( E19="", G19="", I19="", K19="", AND(E19<=64, F19=""), AND(G19<=64, H19=""), AND(I19<=64, J19=""), AND(K19<=64, L19="") ), "", AVERAGE( IF(E19<=64, F19, E19), IF(G19<=64, H19, G19), IF(I19<=64, J19, I19), IF(K19<=64, L19, K19) ) ) | AD19: =IF(COUNT(AA19, AB19, AC19)<3, "", AVERAGE(AA19, AB19, AC19))
A20: 13 | B20: =Datos!B14 | AA20: =IF( OR( C20="", E20="", G20="", I20="", AND(C20<=64, D20=""), AND(E20<=64, F20=""), AND(G20<=64, H20=""), AND(I20<=64, J20="") ), "", AVERAGE( IF(C20<=64, D20, C20), IF(E20<=64, F20, E20), IF(G20<=64, H20, G20), IF(I20<=64, J20, I20) ) ) | AB20: =IF( OR( D20="", F20="", H20="", J20="", AND(D20<=64, E20=""), AND(F20<=64, G20=""), AND(H20<=64, I20=""), AND(J20<=64, K20="") ), "", AVERAGE( IF(D20<=64, E20, D20), IF(F20<=64, G20, F20), IF(H20<=64, I20, H20), IF(J20<=64, K20, J20) ) ) | AC20: =IF( OR( E20="", G20="", I20="", K20="", AND(E20<=64, F20=""), AND(G20<=64, H20=""), AND(I20<=64, J20=""), AND(K20<=64, L20="") ), "", AVERAGE( IF(E20<=64, F20, E20), IF(G20<=64, H20, G20), IF(I20<=64, J20, I20), IF(K20<=64, L20, K20) ) ) | AD20: =IF(COUNT(AA20, AB20, AC20)<3, "", AVERAGE(AA20, AB20, AC20))
... A42: 35 | B42: =Datos!B36 | AA42: =IF( OR( C42="", E42="", G42="", I42="", AND(C42<=64, D42=""), AND(E42<=64, F42=""), AND(G42<=64, H42=""), AND(I42<=64, J42="") ), "", AVERAGE( IF(C42<=64, D42, C42), IF(E42<=64, F42, E42), IF(G42<=64, H42, G42), IF(I42<=64, J42, I42) ) ) | AB42: =IF( OR( D42="", F42="", H42="", J42="", AND(D42<=64, E42=""), AND(F42<=64, G42=""), AND(H42<=64, I42=""), AND(J42<=64, K42="") ), "", AVERAGE( IF(D42<=64, E42, D42), IF(F42<=64, G42, F42), IF(H42<=64, I42, H42), IF(J42<=64, K42, J42) ) ) | AC42: =IF( OR( E42="", G42="", I42="", K42="", AND(E42<=64, F42=""), AND(G42<=64, H42=""), AND(I42<=64, J42=""), AND(K42<=64, L42="") ), "", AVERAGE( IF(E42<=64, F42, E42), IF(G42<=64, H42, G42), IF(I42<=64, J42, I42), IF(K42<=64, L42, K42) ) ) | AD42: =IF(COUNT(AA42, AB42, AC42)<3, "", AVERAGE(AA42, AB42, AC42))

Sheet CIENCIAS SOCIALES
A1: Numero | B1: Nombre/Apellido | C1: Docente: Años Escolar: 2025-2026 Grado: Centro Educativo: Jose Bordas Valdez | E1: =Datos!D2 | AD1: Final de área
C2: Años Escolar: | F2: =Datos!D4
C3: Grado: | E3: =Datos!D6
C4: Centro Educativo: | G4: =Datos!D8
C5: C1. comunicatica | K5: C2. Pensamiento Lógico, Creativo y Crítico | S5: C3. Ética y Ciudadana | AA5: Promedio del área por C.
C7: P1 | D7: R1 | E7: P2 | F7: R2 | G7: P3 | H7: R3 | I7: P4 | J7: R4 | K7: P1 | L7: R1 | M7: P2 | N7: R2 | O7: P3 | P7: R3 | Q7: P4 | R7: R4 | S7: P1 | T7: R1 | U7: P2 | V7: R2 | W7: P3 | X7: R3 | Y7: P4 | Z7: R4 | AA7: C1 | AB7: C2 | AC7: C3
A8: 1 | B8: =Datos!B2 | AA8: =IF( OR( C8="", E8="", G8="", I8="", AND(C8<=64, D8=""), AND(E8<=64, F8=""), AND(G8<=64, H8=""), AND(I8<=64, J8="") ), "", AVERAGE( IF(C8<=64, D8, C8), IF(E8<=64, F8, E8), IF(G8<=64, H8, G8), IF(I8<=64, J8, I8) ) ) | AB8: =IF( OR( K8="", M8="", O8="", Q8="", AND(K8<=64, L8=""), AND(M8<=64, N8=""), AND(O8<=64, P8=""), AND(Q8<=64, R8="") ), "", AVERAGE( IF(K8<=64, L8, K8), IF(M8<=64, N8, M8), IF(O8<=64, P8, O8), IF(Q8<=64, R8, Q8) ) ) | AC8: =IF( OR( S8="", U8="", W8="", Y8="", AND(S8<=64, T8=""), AND(U8<=64, V8=""), AND(W8<=64, X8=""), AND(Y8<=64, Z8="") ), "", AVERAGE( IF(S8<=64, T8, S8), IF(U8<=64, V8, U8), IF(W8<=64, X8, W8), IF(Y8<=64, Z8, Y8) ) ) | AD8: =IF(COUNT(AA8, AB8, AC8)<3, "", AVERAGE(AA8, AB8, AC8))
A9: 2 | B9: =Datos!B3 | AA9: =IF( OR( C9="", E9="", G9="", I9="", AND(C9<=64, D9=""), AND(E9<=64, F9=""), AND(G9<=64, H9=""), AND(I9<=64, J9="") ), "", AVERAGE( IF(C9<=64, D9, C9), IF(E9<=64, F9, E9), IF(G9<=64, H9, G9), IF(I9<=64, J9, I9) ) ) | AB9: =IF( OR( D9="", F9="", H9="", J9="", AND(D9<=64, E9=""), AND(F9<=64, G9=""), AND(H9<=64, I9=""), AND(J9<=64, K9="") ), "", AVERAGE( IF(D9<=64, E9, D9), IF(F9<=64, G9, F9), IF(H9<=64, I9, H9), IF(J9<=64, K9, J9) ) ) | AC9: =IF( OR( E9="", G9="", I9="", K9="", AND(E9<=64, F9=""), AND(G9<=64, H9=""), AND(I9<=64, J9=""), AND(K9<=64, L9="") ), "", AVERAGE( IF(E9<=64, F9, E9), IF(G9<=64, H9, G9), IF(I9<=64, J9, I9), IF(K9<=64, L9, K9) ) ) | AD9: =IF(COUNT(AA9, AB9, AC9)<3, "", AVERAGE(AA9, AB9, AC9))
A10: 3 | B10: =Datos!B4 | AA10: =IF( OR( C10="", E10="", G10="", I10="", AND(C10<=64, D10=""), AND(E10<=64, F10=""), AND(G10<=64, H10=""), AND(I10<=64, J10="") ), "", AVERAGE( IF(C10<=64, D10, C10), IF(E10<=64, F10, E10), IF(G10<=64, H10, G10), IF(I10<=64, J10, I10) ) ) | AB10: =IF( OR( D10="", F10="", H10="", J10="", AND(D10<=64, E10=""), AND(F10<=64, G10=""), AND(H10<=64, I10=""), AND(J10<=64, K10="") ), "", AVERAGE( IF(D10<=64, E10, D10), IF(F10<=64, G10, F10), IF(H10<=64, I10, H10), IF(J10<=64, K10, J10) ) ) | AC10: =IF( OR( E10="", G10="", I10="", K10="", AND(E10<=64, F10=""), AND(G10<=64, H10=""), AND(I10<=64, J10=""), AND(K10<=64, L10="") ), "", AVERAGE( IF(E10<=64, F10, E10), IF(G10<=64, H10, G10), IF(I10<=64, J10, I10), IF(K10<=64, L10, K10) ) ) | AD10: =IF(COUNT(AA10, AB10, AC10)<3, "", AVERAGE(AA10, AB10, AC10))
A11: 4 | B11: =Datos!B5 | AA11: =IF( OR( C11="", E11="", G11="", I11="", AND(C11<=64, D11=""), AND(E11<=64, F11=""), AND(G11<=64, H11=""), AND(I11<=64, J11="") ), "", AVERAGE( IF(C11<=64, D11, C11), IF(E11<=64, F11, E11), IF(G11<=64, H11, G11), IF(I11<=64, J11, I11) ) ) | AB11: =IF( OR( D11="", F11="", H11="", J11="", AND(D11<=64, E11=""), AND(F11<=64, G11=""), AND(H11<=64, I11=""), AND(J11<=64, K11="") ), "", AVERAGE( IF(D11<=64, E11, D11), IF(F11<=64, G11, F11), IF(H11<=64, I11, H11), IF(J11<=64, K11, J11) ) ) | AC11: =IF( OR( E11="", G11="", I11="", K11="", AND(E11<=64, F11=""), AND(G11<=64, H11=""), AND(I11<=64, J11=""), AND(K11<=64, L11="") ), "", AVERAGE( IF(E11<=64, F11, E11), IF(G11<=64, H11, G11), IF(I11<=64, J11, I11), IF(K11<=64, L11, K11) ) ) | AD11: =IF(COUNT(AA11, AB11, AC11)<3, "", AVERAGE(AA11, AB11, AC11))
A12: 5 | B12: =Datos!B6 | AA12: =IF( OR( C12="", E12="", G12="", I12="", AND(C12<=64, D12=""), AND(E12<=64, F12=""), AND(G12<=64, H12=""), AND(I12<=64, J12="") ), "", AVERAGE( IF(C12<=64, D12, C12), IF(E12<=64, F12, E12), IF(G12<=64, H12, G12), IF(I12<=64, J12, I12) ) ) | AB12: =IF( OR( D12="", F12="", H12="", J12="", AND(D12<=64, E12=""), AND(F12<=64, G12=""), AND(H12<=64, I12=""), AND(J12<=64, K12="") ), "", AVERAGE( IF(D12<=64, E12, D12), IF(F12<=64, G12, F12), IF(H12<=64, I12, H12), IF(J12<=64, K12, J12) ) ) | AC12: =IF( OR( E12="", G12="", I12="", K12="", AND(E12<=64, F12=""), AND(G12<=64, H12=""), AND(I12<=64, J12=""), AND(K12<=64, L12="") ), "", AVERAGE( IF(E12<=64, F12, E12), IF(G12<=64, H12, G12), IF(I12<=64, J12, I12), IF(K12<=64, L12, K12) ) ) | AD12: =IF(COUNT(AA12, AB12, AC12)<3, "", AVERAGE(AA12, AB12, AC12))
A13: 6 | B13: =Datos!B7 | AA13: =IF( OR( C13="", E13="", G13="", I13="", AND(C13<=64, D13=""), AND(E13<=64, F13=""), AND(G13<=64, H13=""), AND(I13<=64, J13="") ), "", AVERAGE( IF(C13<=64, D13, C13), IF(E13<=64, F13, E13), IF(G13<=64, H13, G13), IF(I13<=64, J13, I13) ) ) | AB13: =IF( OR( D13="", F13="", H13="", J13="", AND(D13<=64, E13=""), AND(F13<=64, G13=""), AND(H13<=64, I13=""), AND(J13<=64, K13="") ), "", AVERAGE( IF(D13<=64, E13, D13), IF(F13<=64, G13, F13), IF(H13<=64, I13, H13), IF(J13<=64, K13, J13) ) ) | AC13: =IF( OR( E13="", G13="", I13="", K13="", AND(E13<=64, F13=""), AND(G13<=64, H13=""), AND(I13<=64, J13=""), AND(K13<=64, L13="") ), "", AVERAGE( IF(E13<=64, F13, E13), IF(G13<=64, H13, G13), IF(I13<=64, J13, I13), IF(K13<=64, L13, K13) ) ) | AD13: =IF(COUNT(AA13, AB13, AC13)<3, "", AVERAGE(AA13, AB13, AC13))
A14: 7 | B14: =Datos!B8 | AA14: =IF( OR( C14="", E14="", G14="", I14="", AND(C14<=64, D14=""), AND(E14<=64, F14=""), AND(G14<=64, H14=""), AND(I14<=64, J14="") ), "", AVERAGE( IF(C14<=64, D14, C14), IF(E14<=64, F14, E14), IF(G14<=64, H14, G14), IF(I14<=64, J14, I14) ) ) | AB14: =IF( OR( D14="", F14="", H14="", J14="", AND(D14<=64, E14=""), AND(F14<=64, G14=""), AND(H14<=64, I14=""), AND(J14<=64, K14="") ), "", AVERAGE( IF(D14<=64, E14, D14), IF(F14<=64, G14, F14), IF(H14<=64, I14, H14), IF(J14<=64, K14, J14) ) ) | AC14: =IF( OR( E14="", G14="", I14="", K14="", AND(E14<=64, F14=""), AND(G14<=64, H14=""), AND(I14<=64, J14=""), AND(K14<=64, L14="") ), "", AVERAGE( IF(E14<=64, F14, E14), IF(G14<=64, H14, G14), IF(I14<=64, J14, I14), IF(K14<=64, L14, K14) ) ) | AD14: =IF(COUNT(AA14, AB14, AC14)<3, "", AVERAGE(AA14, AB14, AC14))
A15: 8 | B15: =Datos!B9 | AA15: =IF( OR( C15="", E15="", G15="", I15="", AND(C15<=64, D15=""), AND(E15<=64, F15=""), AND(G15<=64, H15=""), AND(I15<=64, J15="") ), "", AVERAGE( IF(C15<=64, D15, C15), IF(E15<=64, F15, E15), IF(G15<=64, H15, G15), IF(I15<=64, J15, I15) ) ) | AB15: =IF( OR( D15="", F15="", H15="", J15="", AND(D15<=64, E15=""), AND(F15<=64, G15=""), AND(H15<=64, I15=""), AND(J15<=64, K15="") ), "", AVERAGE( IF(D15<=64, E15, D15), IF(F15<=64, G15, F15), IF(H15<=64, I15, H15), IF(J15<=64, K15, J15) ) ) | AC15: =IF( OR( E15="", G15="", I15="", K15="", AND(E15<=64, F15=""), AND(G15<=64, H15=""), AND(I15<=64, J15=""), AND(K15<=64, L15="") ), "", AVERAGE( IF(E15<=64, F15, E15), IF(G15<=64, H15, G15), IF(I15<=64, J15, I15), IF(K15<=64, L15, K15) ) ) | AD15: =IF(COUNT(AA15, AB15, AC15)<3, "", AVERAGE(AA15, AB15, AC15))
A16: 9 | B16: =Datos!B10 | AA16: =IF( OR( C16="", E16="", G16="", I16="", AND(C16<=64, D16=""), AND(E16<=64, F16=""), AND(G16<=64, H16=""), AND(I16<=64, J16="") ), "", AVERAGE( IF(C16<=64, D16, C16), IF(E16<=64, F16, E16), IF(G16<=64, H16, G16), IF(I16<=64, J16, I16) ) ) | AB16: =IF( OR( D16="", F16="", H16="", J16="", AND(D16<=64, E16=""), AND(F16<=64, G16=""), AND(H16<=64, I16=""), AND(J16<=64, K16="") ), "", AVERAGE( IF(D16<=64, E16, D16), IF(F16<=64, G16, F16), IF(H16<=64, I16, H16), IF(J16<=64, K16, J16) ) ) | AC16: =IF( OR( E16="", G16="", I16="", K16="", AND(E16<=64, F16=""), AND(G16<=64, H16=""), AND(I16<=64, J16=""), AND(K16<=64, L16="") ), "", AVERAGE( IF(E16<=64, F16, E16), IF(G16<=64, H16, G16), IF(I16<=64, J16, I16), IF(K16<=64, L16, K16) ) ) | AD16: =IF(COUNT(AA16, AB16, AC16)<3, "", AVERAGE(AA16, AB16, AC16))
A17: 10 | B17: =Datos!B11 | AA17: =IF( OR( C17="", E17="", G17="", I17="", AND(C17<=64, D17=""), AND(E17<=64, F17=""), AND(G17<=64, H17=""), AND(I17<=64, J17="") ), "", AVERAGE( IF(C17<=64, D17, C17), IF(E17<=64, F17, E17), IF(G17<=64, H17, G17), IF(I17<=64, J17, I17) ) ) | AB17: =IF( OR( D17="", F17="", H17="", J17="", AND(D17<=64, E17=""), AND(F17<=64, G17=""), AND(H17<=64, I17=""), AND(J17<=64, K17="") ), "", AVERAGE( IF(D17<=64, E17, D17), IF(F17<=64, G17, F17), IF(H17<=64, I17, H17), IF(J17<=64, K17, J17) ) ) | AC17: =IF( OR( E17="", G17="", I17="", K17="", AND(E17<=64, F17=""), AND(G17<=64, H17=""), AND(I17<=64, J17=""), AND(K17<=64, L17="") ), "", AVERAGE( IF(E17<=64, F17, E17), IF(G17<=64, H17, G17), IF(I17<=64, J17, I17), IF(K17<=64, L17, K17) ) ) | AD17: =IF(COUNT(AA17, AB17, AC17)<3, "", AVERAGE(AA17, AB17, AC17))
A18: 11 | B18: =Datos!B12 | AA18: =IF( OR( C18="", E18="", G18="", I18="", AND(C18<=64, D18=""), AND(E18<=64, F18=""), AND(G18<=64, H18=""), AND(I18<=64, J18="") ), "", AVERAGE( IF(C18<=64, D18, C18), IF(E18<=64, F18, E18), IF(G18<=64, H18, G18), IF(I18<=64, J18, I18) ) ) | AB18: =IF( OR( D18="", F18="", H18="", J18="", AND(D18<=64, E18=""), AND(F18<=64, G18=""), AND(H18<=64, I18=""), AND(J18<=64, K18="") ), "", AVERAGE( IF(D18<=64, E18, D18), IF(F18<=64, G18, F18), IF(H18<=64, I18, H18), IF(J18<=64, K18, J18) ) ) | AC18: =IF( OR( E18="", G18="", I18="", K18="", AND(E18<=64, F18=""), AND(G18<=64, H18=""), AND(I18<=64, J18=""), AND(K18<=64, L18="") ), "", AVERAGE( IF(E18<=64, F18, E18), IF(G18<=64, H18, G18), IF(I18<=64, J18, I18), IF(K18<=64, L18, K18) ) ) | AD18: =IF(COUNT(AA18, AB18, AC18)<3, "", AVERAGE(AA18, AB18, AC18))
A19: 12 | B19: =Datos!B13 | AA19: =IF( OR( C19="", E19="", G19="", I19="", AND(C19<=64, D19=""), AND(E19<=64, F19=""), AND(G19<=64, H19=""), AND(I19<=64, J19="") ), "", AVERAGE( IF(C19<=64, D19, C19), IF(E19<=64, F19, E19), IF(G19<=64, H19, G19), IF(I19<=64, J19, I19) ) ) | AB19: =IF( OR( D19="", F19="", H19="", J19="", AND(D19<=64, E19=""), AND(F19<=64, G19=""), AND(H19<=64, I19=""), AND(J19<=64, K19="") ), "", AVERAGE( IF(D19<=64, E19, D19), IF(F19<=64, G19, F19), IF(H19<=64, I19, H19), IF(J19<=64, K19, J19) ) ) | AC19: =IF( OR( E19="", G19="", I19="", K19="", AND(E19<=64, F19=""), AND(G19<=64, H19=""), AND(I19<=64, J19=""), AND(K19<=64, L19="") ), "", AVERAGE( IF(E19<=64, F19, E19), IF(G19<=64, H19, G19), IF(I19<=64, J19, I19), IF(K19<=64, L19, K19) ) ) | AD19: =IF(COUNT(AA19, AB19, AC19)<3, "", AVERAGE(AA19, AB19, AC19))
A20: 13 | B20: =Datos!B14 | AA20: =IF( OR( C20="", E20="", G20="", I20="", AND(C20<=64, D20=""), AND(E20<=64, F20=""), AND(G20<=64, H20=""), AND(I20<=64, J20="") ), "", AVERAGE( IF(C20<=64, D20, C20), IF(E20<=64, F20, E20), IF(G20<=64, H20, G20), IF(I20<=64, J20, I20) ) ) | AB20: =IF( OR( D20="", F20="", H20="", J20="", AND(D20<=64, E20=""), AND(F20<=64, G20=""), AND(H20<=64, I20=""), AND(J20<=64, K20="") ), "", AVERAGE( IF(D20<=64, E20, D20), IF(F20<=64, G20, F20), IF(H20<=64, I20, H20), IF(J20<=64, K20, J20) ) ) | AC20: =IF( OR( E20="", G20="", I20="", K20="", AND(E20<=64, F20=""), AND(G20<=64, H20=""), AND(I20<=64, J20=""), AND(K20<=64, L20="") ), "", AVERAGE( IF(E20<=64, F20, E20), IF(G20<=64, H20, G20), IF(I20<=64, J20, I20), IF(K20<=64, L20, K20) ) ) | AD20: =IF(COUNT(AA20, AB20, AC20)<3, "", AVERAGE(AA20, AB20, AC20))
... A42: 35 | B42: =Datos!B36 | AA42: =IF( OR( C42="", E42="", G42="", I42="", AND(C42<=64, D42=""), AND(E42<=64, F42=""), AND(G42<=64, H42=""), AND(I42<=64, J42="") ), "", AVERAGE( IF(C42<=64, D42, C42), IF(E42<=64, F42, E42), IF(G42<=64, H42, G42), IF(I42<=64, J42, I42) ) ) | AB42: =IF( OR( D42="", F42="", H42="", J42="", AND(D42<=64, E42=""), AND(F42<=64, G42=""), AND(H42<=64, I42=""), AND(J42<=64, K42="") ), "", AVERAGE( IF(D42<=64, E42, D42), IF(F42<=64, G42, F42), IF(H42<=64, I42, H42), IF(J42<=64, K42, J42) ) ) | AC42: =IF( OR( E42="", G42="", I42="", K42="", AND(E42<=64, F42=""), AND(G42<=64, H42=""), AND(I42<=64, J42=""), AND(K42<=64, L42="") ), "", AVERAGE( IF(E42<=64, F42, E42), IF(G42<=64, H42, G42), IF(I42<=64, J42, I42), IF(K42<=64, L42, K42) ) ) | AD42: =IF(COUNT(AA42, AB42, AC42)<3, "", AVERAGE(AA42, AB42, AC42))

Sheet CIENCIAS NATURALES
A1: Numero | B1: Nombre/Apellido | C1: Docente: Años Escolar: 2025-2026 Grado: Centro Educativo: Jose Bordas Valdez | E1: =Datos!D2 | AD1: Final de área
C2: Años Escolar: | F2: =Datos!D4
C3: Grado: | E3: =Datos!D6
C4: Centro Educativo: | G4: =Datos!D8
C5: C1. comunicatica | K5: C2. Pensamiento Lógico, Creativo y Crítico | S5: C3. Ética y Ciudadana | AA5: Promedio del área por C.
C7: P1 | D7: R1 | E7: P2 | F7: R2 | G7: P3 | H7: R3 | I7: P4 | J7: R4 | K7: P1 | L7: R1 | M7: P2 | N7: R2 | O7: P3 | P7: R3 | Q7: P4 | R7: R4 | S7: P1 | T7: R1 | U7: P2 | V7: R2 | W7: P3 | X7: R3 | Y7: P4 | Z7: R4 | AA7: C1 | AB7: C2 | AC7: C3
A8: 1 | B8: =Datos!B2 | AA8: =IF( OR( C8="", E8="", G8="", I8="", AND(C8<=64, D8=""), AND(E8<=64, F8=""), AND(G8<=64, H8=""), AND(I8<=64, J8="") ), "", AVERAGE( IF(C8<=64, D8, C8), IF(E8<=64, F8, E8), IF(G8<=64, H8, G8), IF(I8<=64, J8, I8) ) ) | AB8: =IF( OR( K8="", M8="", O8="", Q8="", AND(K8<=64, L8=""), AND(M8<=64, N8=""), AND(O8<=64, P8=""), AND(Q8<=64, R8="") ), "", AVERAGE( IF(K8<=64, L8, K8), IF(M8<=64, N8, M8), IF(O8<=64, P8, O8), IF(Q8<=64, R8, Q8) ) ) | AC8: =IF( OR( S8="", U8="", W8="", Y8="", AND(S8<=64, T8=""), AND(U8<=64, V8=""), AND(W8<=64, X8=""), AND(Y8<=64, Z8="") ), "", AVERAGE( IF(S8<=64, T8, S8), IF(U8<=64, V8, U8), IF(W8<=64, X8, W8), IF(Y8<=64, Z8, Y8) ) ) | AD8: =IF(COUNT(AA8, AB8, AC8)<3, "", AVERAGE(AA8, AB8, AC8))
A9: 2 | B9: =Datos!B3 | AA9: =IF( OR( C9="", E9="", G9="", I9="", AND(C9<=64, D9=""), AND(E9<=64, F9=""), AND(G9<=64, H9=""), AND(I9<=64, J9="") ), "", AVERAGE( IF(C9<=64, D9, C9), IF(E9<=64, F9, E9), IF(G9<=64, H9, G9), IF(I9<=64, J9, I9) ) ) | AB9: =IF( OR( D9="", F9="", H9="", J9="", AND(D9<=64, E9=""), AND(F9<=64, G9=""), AND(H9<=64, I9=""), AND(J9<=64, K9="") ), "", AVERAGE( IF(D9<=64, E9, D9), IF(F9<=64, G9, F9), IF(H9<=64, I9, H9), IF(J9<=64, K9, J9) ) ) | AC9: =IF( OR( E9="", G9="", I9="", K9="", AND(E9<=64, F9=""), AND(G9<=64, H9=""), AND(I9<=64, J9=""), AND(K9<=64, L9="") ), "", AVERAGE( IF(E9<=64, F9, E9), IF(G9<=64, H9, G9), IF(I9<=64, J9, I9), IF(K9<=64, L9, K9) ) ) | AD9: =IF(COUNT(AA9, AB9, AC9)<3, "", AVERAGE(AA9, AB9, AC9))
A10: 3 | B10: =Datos!B4 | AA10: =IF( OR( C10="", E10="", G10="", I10="", AND(C10<=64, D10=""), AND(E10<=64, F10=""), AND(G10<=64, H10=""), AND(I10<=64, J10="") ), "", AVERAGE( IF(C10<=64, D10, C10), IF(E10<=64, F10, E10), IF(G10<=64, H10, G10), IF(I10<=64, J10, I10) ) ) | AB10: =IF( OR( D10="", F10="", H10="", J10="", AND(D10<=64, E10=""), AND(F10<=64, G10=""), AND(H10<=64, I10=""), AND(J10<=64, K10="") ), "", AVERAGE( IF(D10<=64, E10, D10), IF(F10<=64, G10, F10), IF(H10<=64, I10, H10), IF(J10<=64, K10, J10) ) ) | AC10: =IF( OR( E10="", G10="", I10="", K10="", AND(E10<=64, F10=""), AND(G10<=64, H10=""), AND(I10<=64, J10=""), AND(K10<=64, L10="") ), "", AVERAGE( IF(E10<=64, F10, E10), IF(G10<=64, H10, G10), IF(I10<=64, J10, I10), IF(K10<=64, L10, K10) ) ) | AD10: =IF(COUNT(AA10, AB10, AC10)<3, "", AVERAGE(AA10, AB10, AC10))
A11: 4 | B11: =Datos!B5 | AA11: =IF( OR( C11="", E11="", G11="", I11="", AND(C11<=64, D11=""), AND(E11<=64, F11=""), AND(G11<=64, H11=""), AND(I11<=64, J11="") ), "", AVERAGE( IF(C11<=64, D11, C11), IF(E11<=64, F11, E11), IF(G11<=64, H11, G11), IF(I11<=64, J11, I11) ) ) | AB11: =IF( OR( D11="", F11="", H11="", J11="", AND(D11<=64, E11=""), AND(F11<=64, G11=""), AND(H11<=64, I11=""), AND(J11<=64, K11="") ), "", AVERAGE( IF(D11<=64, E11, D11), IF(F11<=64, G11, F11), IF(H11<=64, I11, H11), IF(J11<=64, K11, J11) ) ) | AC11: =IF( OR( E11="", G11="", I11="", K11="", AND(E11<=64, F11=""), AND(G11<=64, H11=""), AND(I11<=64, J11=""), AND(K11<=64, L11="") ), "", AVERAGE( IF(E11<=64, F11, E11), IF(G11<=64, H11, G11), IF(I11<=64, J11, I11), IF(K11<=64, L11, K11) ) ) | AD11: =IF(COUNT(AA11, AB11, AC11)<3, "", AVERAGE(AA11, AB11, AC11))
A12: 5 | B12: =Datos!B6 | AA12: =IF( OR( C12="", E12="", G12="", I12="", AND(C12<=64, D12=""), AND(E12<=64, F12=""), AND(G12<=64, H12=""), AND(I12<=64, J12="") ), "", AVERAGE( IF(C12<=64, D12, C12), IF(E12<=64, F12, E12), IF(G12<=64, H12, G12), IF(I12<=64, J12, I12) ) ) | AB12: =IF( OR( D12="", F12="", H12="", J12="", AND(D12<=64, E12=""), AND(F12<=64, G12=""), AND(H12<=64, I12=""), AND(J12<=64, K12="") ), "", AVERAGE( IF(D12<=64, E12, D12), IF(F12<=64, G12, F12), IF(H12<=64, I12, H12), IF(J12<=64, K12, J12) ) ) | AC12: =IF( OR( E12="", G12="", I12="", K12="", AND(E12<=64, F12=""), AND(G12<=64, H12=""), AND(I12<=64, J12=""), AND(K12<=64, L12="") ), "", AVERAGE( IF(E12<=64, F12, E12), IF(G12<=64, H12, G12), IF(I12<=64, J12, I12), IF(K12<=64, L12, K12) ) ) | AD12: =IF(COUNT(AA12, AB12, AC12)<3, "", AVERAGE(AA12, AB12, AC12))
A13: 6 | B13: =Datos!B7 | AA13: =IF( OR( C13="", E13="", G13="", I13="", AND(C13<=64, D13=""), AND(E13<=64, F13=""), AND(G13<=64, H13=""), AND(I13<=64, J13="") ), "", AVERAGE( IF(C13<=64, D13, C13), IF(E13<=64, F13, E13), IF(G13<=64, H13, G13), IF(I13<=64, J13, I13) ) ) | AB13: =IF( OR( D13="", F13="", H13="", J13="", AND(D13<=64, E13=""), AND(F13<=64, G13=""), AND(H13<=64, I13=""), AND(J13<=64, K13="") ), "", AVERAGE( IF(D13<=64, E13, D13), IF(F13<=64, G13, F13), IF(H13<=64, I13, H13), IF(J13<=64, K13, J13) ) ) | AC13: =IF( OR( E13="", G13="", I13="", K13="", AND(E13<=64, F13=""), AND(G13<=64, H13=""), AND(I13<=64, J13=""), AND(K13<=64, L13="") ), "", AVERAGE( IF(E13<=64, F13, E13), IF(G13<=64, H13, G13), IF(I13<=64, J13, I13), IF(K13<=64, L13, K13) ) ) | AD13: =IF(COUNT(AA13, AB13, AC13)<3, "", AVERAGE(AA13, AB13, AC13))
A14: 7 | B14: =Datos!B8 | AA14: =IF( OR( C14="", E14="", G14="", I14="", AND(C14<=64, D14=""), AND(E14<=64, F14=""), AND(G14<=64, H14=""), AND(I14<=64, J14="") ), "", AVERAGE( IF(C14<=64, D14, C14), IF(E14<=64, F14, E14), IF(G14<=64, H14, G14), IF(I14<=64, J14, I14) ) ) | AB14: =IF( OR( D14="", F14="", H14="", J14="", AND(D14<=64, E14=""), AND(F14<=64, G14=""), AND(H14<=64, I14=""), AND(J14<=64, K14="") ), "", AVERAGE( IF(D14<=64, E14, D14), IF(F14<=64, G14, F14), IF(H14<=64, I14, H14), IF(J14<=64, K14, J14) ) ) | AC14: =IF( OR( E14="", G14="", I14="", K14="", AND(E14<=64, F14=""), AND(G14<=64, H14=""), AND(I14<=64, J14=""), AND(K14<=64, L14="") ), "", AVERAGE( IF(E14<=64, F14, E14), IF(G14<=64, H14, G14), IF(I14<=64, J14, I14), IF(K14<=64, L14, K14) ) ) | AD14: =IF(COUNT(AA14, AB14, AC14)<3, "", AVERAGE(AA14, AB14, AC14))
A15: 8 | B15: =Datos!B9 | AA15: =IF( OR( C15="", E15="", G15="", I15="", AND(C15<=64, D15=""), AND(E15<=64, F15=""), AND(G15<=64, H15=""), AND(I15<=64, J15="") ), "", AVERAGE( IF(C15<=64, D15, C15), IF(E15<=64, F15, E15), IF(G15<=64, H15, G15), IF(I15<=64, J15, I15) ) ) | AB15: =IF( OR( D15="", F15="", H15="", J15="", AND(D15<=64, E15=""), AND(F15<=64, G15=""), AND(H15<=64, I15=""), AND(J15<=64, K15="") ), "", AVERAGE( IF(D15<=64, E15, D15), IF(F15<=64, G15, F15), IF(H15<=64, I15, H15), IF(J15<=64, K15, J15) ) ) | AC15: =IF( OR( E15="", G15="", I15="", K15="", AND(E15<=64, F15=""), AND(G15<=64, H15=""), AND(I15<=64, J15=""), AND(K15<=64, L15="") ), "", AVERAGE( IF(E15<=64, F15, E15), IF(G15<=64, H15, G15), IF(I15<=64, J15, I15), IF(K15<=64, L15, K15) ) ) | AD15: =IF(COUNT(AA15, AB15, AC15)<3, "", AVERAGE(AA15, AB15, AC15))
A16: 9 | B16: =Datos!B10 | AA16: =IF( OR( C16="", E16="", G16="", I16="", AND(C16<=64, D16=""), AND(E16<=64, F16=""), AND(G16<=64, H16=""), AND(I16<=64, J16="") ), "", AVERAGE( IF(C16<=64, D16, C16), IF(E16<=64, F16, E16), IF(G16<=64, H16, G16), IF(I16<=64, J16, I16) ) ) | AB16: =IF( OR( D16="", F16="", H16="", J16="", AND(D16<=64, E16=""), AND(F16<=64, G16=""), AND(H16<=64, I16=""), AND(J16<=64, K16="") ), "", AVERAGE( IF(D16<=64, E16, D16), IF(F16<=64, G16, F16), IF(H16<=64, I16, H16), IF(J16<=64, K16, J16) ) ) | AC16: =IF( OR( E16="", G16="", I16="", K16="", AND(E16<=64, F16=""), AND(G16<=64, H16=""), AND(I16<=64, J16=""), AND(K16<=64, L16="") ), "", AVERAGE( IF(E16<=64, F16, E16), IF(G16<=64, H16, G16), IF(I16<=64, J16, I16), IF(K16<=64, L16, K16) ) ) | AD16: =IF(COUNT(AA16, AB16, AC16)<3, "", AVERAGE(AA16, AB16, AC16))
A17: 10 | B17: =Datos!B11 | AA17: =IF( OR( C17="", E17="", G17="", I17="", AND(C17<=64, D17=""), AND(E17<=64, F17=""), AND(G17<=64, H17=""), AND(I17<=64, J17="") ), "", AVERAGE( IF(C17<=64, D17, C17), IF(E17<=64, F17, E17), IF(G17<=64, H17, G17), IF(I17<=64, J17, I17) ) ) | AB17: =IF( OR( D17="", F17="", H17="", J17="", AND(D17<=64, E17=""), AND(F17<=64, G17=""), AND(H17<=64, I17=""), AND(J17<=64, K17="") ), "", AVERAGE( IF(D17<=64, E17, D17), IF(F17<=64, G17, F17), IF(H17<=64, I17, H17), IF(J17<=64, K17, J17) ) ) | AC17: =IF( OR( E17="", G17="", I17="", K17="", AND(E17<=64, F17=""), AND(G17<=64, H17=""), AND(I17<=64, J17=""), AND(K17<=64, L17="") ), "", AVERAGE( IF(E17<=64, F17, E17), IF(G17<=64, H17, G17), IF(I17<=64, J17, I17), IF(K17<=64, L17, K17) ) ) | AD17: =IF(COUNT(AA17, AB17, AC17)<3, "", AVERAGE(AA17, AB17, AC17))
A18: 11 | B18: =Datos!B12 | AA18: =IF( OR( C18="", E18="", G18="", I18="", AND(C18<=64, D18=""), AND(E18<=64, F18=""), AND(G18<=64, H18=""), AND(I18<=64, J18="") ), "", AVERAGE( IF(C18<=64, D18, C18), IF(E18<=64, F18, E18), IF(G18<=64, H18, G18), IF(I18<=64, J18, I18) ) ) | AB18: =IF( OR( D18="", F18="", H18="", J18="", AND(D18<=64, E18=""), AND(F18<=64, G18=""), AND(H18<=64, I18=""), AND(J18<=64, K18="") ), "", AVERAGE( IF(D18<=64, E18, D18), IF(F18<=64, G18, F18), IF(H18<=64, I18, H18), IF(J18<=64, K18, J18) ) ) | AC18: =IF( OR( E18="", G18="", I18="", K18="", AND(E18<=64, F18=""), AND(G18<=64, H18=""), AND(I18<=64, J18=""), AND(K18<=64, L18="") ), "", AVERAGE( IF(E18<=64, F18, E18), IF(G18<=64, H18, G18), IF(I18<=64, J18, I18), IF(K18<=64, L18, K18) ) ) | AD18: =IF(COUNT(AA18, AB18, AC18)<3, "", AVERAGE(AA18, AB18, AC18))
A19: 12 | B19: =Datos!B13 | AA19: =IF( OR( C19="", E19="", G19="", I19="", AND(C19<=64, D19=""), AND(E19<=64, F19=""), AND(G19<=64, H19=""), AND(I19<=64, J19="") ), "", AVERAGE( IF(C19<=64, D19, C19), IF(E19<=64, F19, E19), IF(G19<=64, H19, G19), IF(I19<=64, J19, I19) ) ) | AB19: =IF( OR( D19="", F19="", H19="", J19="", AND(D19<=64, E19=""), AND(F19<=64, G19=""), AND(H19<=64, I19=""), AND(J19<=64, K19="") ), "", AVERAGE( IF(D19<=64, E19, D19), IF(F19<=64, G19, F19), IF(H19<=64, I19, H19), IF(J19<=64, K19, J19) ) ) | AC19: =IF( OR( E19="", G19="", I19="", K19="", AND(E19<=64, F19=""), AND(G19<=64, H19=""), AND(I19<=64, J19=""), AND(K19<=64, L19="") ), "", AVERAGE( IF(E19<=64, F19, E19), IF(G19<=64, H19, G19), IF(I19<=64, J19, I19), IF(K19<=64, L19, K19) ) ) | AD19: =IF(COUNT(AA19, AB19, AC19)<3, "", AVERAGE(AA19, AB19, AC19))
A20: 13 | B20: =Datos!B14 | AA20: =IF( OR( C20="", E20="", G20="", I20="", AND(C20<=64, D20=""), AND(E20<=64, F20=""), AND(G20<=64, H20=""), AND(I20<=64, J20="") ), "", AVERAGE( IF(C20<=64, D20, C20), IF(E20<=64, F20, E20), IF(G20<=64, H20, G20), IF(I20<=64, J20, I20) ) ) | AB20: =IF( OR( D20="", F20="", H20="", J20="", AND(D20<=64, E20=""), AND(F20<=64, G20=""), AND(H20<=64, I20=""), AND(J20<=64, K20="") ), "", AVERAGE( IF(D20<=64, E20, D20), IF(F20<=64, G20, F20), IF(H20<=64, I20, H20), IF(J20<=64, K20, J20) ) ) | AC20: =IF( OR( E20="", G20="", I20="", K20="", AND(E20<=64, F20=""), AND(G20<=64, H20=""), AND(I20<=64, J20=""), AND(K20<=64, L20="") ), "", AVERAGE( IF(E20<=64, F20, E20), IF(G20<=64, H20, G20), IF(I20<=64, J20, I20), IF(K20<=64, L20, K20) ) ) | AD20: =IF(COUNT(AA20, AB20, AC20)<3, "", AVERAGE(AA20, AB20, AC20))
... A42: 35 | B42: =Datos!B36 | AA42: =IF( OR( C42="", E42="", G42="", I42="", AND(C42<=64, D42=""), AND(E42<=64, F42=""), AND(G42<=64, H42=""), AND(I42<=64, J42="") ), "", AVERAGE( IF(C42<=64, D42, C42), IF(E42<=64, F42, E42), IF(G42<=64, H42, G42), IF(I42<=64, J42, I42) ) ) | AB42: =IF( OR( D42="", F42="", H42="", J42="", AND(D42<=64, E42=""), AND(F42<=64, G42=""), AND(H42<=64, I42=""), AND(J42<=64, K42="") ), "", AVERAGE( IF(D42<=64, E42, D42), IF(F42<=64, G42, F42), IF(H42<=64, I42, H42), IF(J42<=64, K42, J42) ) ) | AC42: =IF( OR( E42="", G42="", I42="", K42="", AND(E42<=64, F42=""), AND(G42<=64, H42=""), AND(I42<=64, J42=""), AND(K42<=64, L42="") ), "", AVERAGE( IF(E42<=64, F42, E42), IF(G42<=64, H42, G42), IF(I42<=64, J42, I42), IF(K42<=64, L42, K42) ) ) | AD42: =IF(COUNT(AA42, AB42, AC42)<3, "", AVERAGE(AA42, AB42, AC42))

Sheet EDUCACIÓN FÍSICA
A1: Numero | B1: Nombre/Apellido | C1: Docente: Años Escolar: 2025-2026 Grado: Centro Educativo: Jose Bordas Valdez | E1: =Datos!D2 | AD1: Final de área
C2: Años Escolar: | F2: =Datos!D4
C3: Grado: | E3: =Datos!D6
C4: Centro Educativo: | G4: =Datos!D8
C5: C1. comunicatica | K5: C2. Pensamiento Lógico, Creativo y Crítico | S5: C3. Ética y Ciudadana | AA5: Promedio del área por C.
C7: P1 | D7: R1 | E7: P2 | F7: R2 | G7: P3 | H7: R3 | I7: P4 | J7: R4 | K7: P1 | L7: R1 | M7: P2 | N7: R2 | O7: P3 | P7: R3 | Q7: P4 | R7: R4 | S7: P1 | T7: R1 | U7: P2 | V7: R2 | W7: P3 | X7: R3 | Y7: P4 | Z7: R4 | AA7: C1 | AB7: C2 | AC7: C3
A8: 1 | B8: =Datos!B2 | AA8: =IF( OR( C8="", E8="", G8="", I8="", AND(C8<=64, D8=""), AND(E8<=64, F8=""), AND(G8<=64, H8=""), AND(I8<=64, J8="") ), "", AVERAGE( IF(C8<=64, D8, C8), IF(E8<=64, F8, E8), IF(G8<=64, H8, G8), IF(I8<=64, J8, I8) ) ) | AB8: =IF( OR( K8="", M8="", O8="", Q8="", AND(K8<=64, L8=""), AND(M8<=64, N8=""), AND(O8<=64, P8=""), AND(Q8<=64, R8="") ), "", AVERAGE( IF(K8<=64, L8, K8), IF(M8<=64, N8, M8), IF(O8<=64, P8, O8), IF(Q8<=64, R8, Q8) ) ) | AC8: =IF( OR( S8="", U8="", W8="", Y8="", AND(S8<=64, T8=""), AND(U8<=64, V8=""), AND(W8<=64, X8=""), AND(Y8<=64, Z8="") ), "", AVERAGE( IF(S8<=64, T8, S8), IF(U8<=64, V8, U8), IF(W8<=64, X8, W8), IF(Y8<=64, Z8, Y8) ) ) | AD8: =IF(COUNT(AA8, AB8, AC8)<3, "", AVERAGE(AA8, AB8, AC8))
A9: 2 | B9: =Datos!B3 | AA9: =IF( OR( C9="", E9="", G9="", I9="", AND(C9<=64, D9=""), AND(E9<=64, F9=""), AND(G9<=64, H9=""), AND(I9<=64, J9="") ), "", AVERAGE( IF(C9<=64, D9, C9), IF(E9<=64, F9, E9), IF(G9<=64, H9, G9), IF(I9<=64, J9, I9) ) ) | AB9: =IF( OR( D9="", F9="", H9="", J9="", AND(D9<=64, E9=""), AND(F9<=64, G9=""), AND(H9<=64, I9=""), AND(J9<=64, K9="") ), "", AVERAGE( IF(D9<=64, E9, D9), IF(F9<=64, G9, F9), IF(H9<=64, I9, H9), IF(J9<=64, K9, J9) ) ) | AC9: =IF( OR( E9="", G9="", I9="", K9="", AND(E9<=64, F9=""), AND(G9<=64, H9=""), AND(I9<=64, J9=""), AND(K9<=64, L9="") ), "", AVERAGE( IF(E9<=64, F9, E9), IF(G9<=64, H9, G9), IF(I9<=64, J9, I9), IF(K9<=64, L9, K9) ) ) | AD9: =IF(COUNT(AA9, AB9, AC9)<3, "", AVERAGE(AA9, AB9, AC9))
A10: 3 | B10: =Datos!B4 | AA10: =IF( OR( C10="", E10="", G10="", I10="", AND(C10<=64, D10=""), AND(E10<=64, F10=""), AND(G10<=64, H10=""), AND(I10<=64, J10="") ), "", AVERAGE( IF(C10<=64, D10, C10), IF(E10<=64, F10, E10), IF(G10<=64, H10, G10), IF(I10<=64, J10, I10) ) ) | AB10: =IF( OR( D10="", F10="", H10="", J10="", AND(D10<=64, E10=""), AND(F10<=64, G10=""), AND(H10<=64, I10=""), AND(J10<=64, K10="") ), "", AVERAGE( IF(D10<=64, E10, D10), IF(F10<=64, G10, F10), IF(H10<=64, I10, H10), IF(J10<=64, K10, J10) ) ) | AC10: =IF( OR( E10="", G10="", I10="", K10="", AND(E10<=64, F10=""), AND(G10<=64, H10=""), AND(I10<=64, J10=""), AND(K10<=64, L10="") ), "", AVERAGE( IF(E10<=64, F10, E10), IF(G10<=64, H10, G10), IF(I10<=64, J10, I10), IF(K10<=64, L10, K10) ) ) | AD10: =IF(COUNT(AA10, AB10, AC10)<3, "", AVERAGE(AA10, AB10, AC10))
A11: 4 | B11: =Datos!B5 | AA11: =IF( OR( C11="", E11="", G11="", I11="", AND(C11<=64, D11=""), AND(E11<=64, F11=""), AND(G11<=64, H11=""), AND(I11<=64, J11="") ), "", AVERAGE( IF(C11<=64, D11, C11), IF(E11<=64, F11, E11), IF(G11<=64, H11, G11), IF(I11<=64, J11, I11) ) ) | AB11: =IF( OR( D11="", F11="", H11="", J11="", AND(D11<=64, E11=""), AND(F11<=64, G11=""), AND(H11<=64, I11=""), AND(J11<=64, K11="") ), "", AVERAGE( IF(D11<=64, E11, D11), IF(F11<=64, G11, F11), IF(H11<=64, I11, H11), IF(J11<=64, K11, J11) ) ) | AC11: =IF( OR( E11="", G11="", I11="", K11="", AND(E11<=64, F11=""), AND(G11<=64, H11=""), AND(I11<=64, J11=""), AND(K11<=64, L11="") ), "", AVERAGE( IF(E11<=64, F11, E11), IF(G11<=64, H11, G11), IF(I11<=64, J11, I11), IF(K11<=64, L11, K11) ) ) | AD11: =IF(COUNT(AA11, AB11, AC11)<3, "", AVERAGE(AA11, AB11, AC11))
A12: 5 | B12: =Datos!B6 | AA12: =IF( OR( C12="", E12="", G12="", I12="", AND(C12<=64, D12=""), AND(E12<=64, F12=""), AND(G12<=64, H12=""), AND(I12<=64, J12="") ), "", AVERAGE( IF(C12<=64, D12, C12), IF(E12<=64, F12, E12), IF(G12<=64, H12, G12), IF(I12<=64, J12, I12) ) ) | AB12: =IF( OR( D12="", F12="", H12="", J12="", AND(D12<=64, E12=""), AND(F12<=64, G12=""), AND(H12<=64, I12=""), AND(J12<=64, K12="") ), "", AVERAGE( IF(D12<=64, E12, D12), IF(F12<=64, G12, F12), IF(H12<=64, I12, H12), IF(J12<=64, K12, J12) ) ) | AC12: =IF( OR( E12="", G12="", I12="", K12="", AND(E12<=64, F12=""), AND(G12<=64, H12=""), AND(I12<=64, J12=""), AND(K12<=64, L12="") ), "", AVERAGE( IF(E12<=64, F12, E12), IF(G12<=64, H12, G12), IF(I12<=64, J12, I12), IF(K12<=64, L12, K12) ) ) | AD12: =IF(COUNT(AA12, AB12, AC12)<3, "", AVERAGE(AA12, AB12, AC12))
A13: 6 | B13: =Datos!B7 | AA13: =IF( OR( C13="", E13="", G13="", I13="", AND(C13<=64, D13=""), AND(E13<=64, F13=""), AND(G13<=64, H13=""), AND(I13<=64, J13="") ), "", AVERAGE( IF(C13<=64, D13, C13), IF(E13<=64, F13, E13), IF(G13<=64, H13, G13), IF(I13<=64, J13, I13) ) ) | AB13: =IF( OR( D13="", F13="", H13="", J13="", AND(D13<=64, E13=""), AND(F13<=64, G13=""), AND(H13<=64, I13=""), AND(J13<=64, K13="") ), "", AVERAGE( IF(D13<=64, E13, D13), IF(F13<=64, G13, F13), IF(H13<=64, I13, H13), IF(J13<=64, K13, J13) ) ) | AC13: =IF( OR( E13="", G13="", I13="", K13="", AND(E13<=64, F13=""), AND(G13<=64, H13=""), AND(I13<=64, J13=""), AND(K13<=64, L13="") ), "", AVERAGE( IF(E13<=64, F13, E13), IF(G13<=64, H13, G13), IF(I13<=64, J13, I13), IF(K13<=64, L13, K13) ) ) | AD13: =IF(COUNT(AA13, AB13, AC13)<3, "", AVERAGE(AA13, AB13, AC13))
A14: 7 | B14: =Datos!B8 | AA14: =IF( OR( C14="", E14="", G14="", I14="", AND(C14<=64, D14=""), AND(E14<=64, F14=""), AND(G14<=64, H14=""), AND(I14<=64, J14="") ), "", AVERAGE( IF(C14<=64, D14, C14), IF(E14<=64, F14, E14), IF(G14<=64, H14, G14), IF(I14<=64, J14, I14) ) ) | AB14: =IF( OR( D14="", F14="", H14="", J14="", AND(D14<=64, E14=""), AND(F14<=64, G14=""), AND(H14<=64, I14=""), AND(J14<=64, K14="") ), "", AVERAGE( IF(D14<=64, E14, D14), IF(F14<=64, G14, F14), IF(H14<=64, I14, H14), IF(J14<=64, K14, J14) ) ) | AC14: =IF( OR( E14="", G14="", I14="", K14="", AND(E14<=64, F14=""), AND(G14<=64, H14=""), AND(I14<=64, J14=""), AND(K14<=64, L14="") ), "", AVERAGE( IF(E14<=64, F14, E14), IF(G14<=64, H14, G14), IF(I14<=64, J14, I14), IF(K14<=64, L14, K14) ) ) | AD14: =IF(COUNT(AA14, AB14, AC14)<3, "", AVERAGE(AA14, AB14, AC14))
A15: 8 | B15: =Datos!B9 | AA15: =IF( OR( C15="", E15="", G15="", I15="", AND(C15<=64, D15=""), AND(E15<=64, F15=""), AND(G15<=64, H15=""), AND(I15<=64, J15="") ), "", AVERAGE( IF(C15<=64, D15, C15), IF(E15<=64, F15, E15), IF(G15<=64, H15, G15), IF(I15<=64, J15, I15) ) ) | AB15: =IF( OR( D15="", F15="", H15="", J15="", AND(D15<=64, E15=""), AND(F15<=64, G15=""), AND(H15<=64, I15=""), AND(J15<=64, K15="") ), "", AVERAGE( IF(D15<=64, E15, D15), IF(F15<=64, G15, F15), IF(H15<=64, I15, H15), IF(J15<=64, K15, J15) ) ) | AC15: =IF( OR( E15="", G15="", I15="", K15="", AND(E15<=64, F15=""), AND(G15<=64, H15=""), AND(I15<=64, J15=""), AND(K15<=64, L15="") ), "", AVERAGE( IF(E15<=64, F15, E15), IF(G15<=64, H15, G15), IF(I15<=64, J15, I15), IF(K15<=64, L15, K15) ) ) | AD15: =IF(COUNT(AA15, AB15, AC15)<3, "", AVERAGE(AA15, AB15, AC15))
A16: 9 | B16: =Datos!B10 | AA16: =IF( OR( C16="", E16="", G16="", I16="", AND(C16<=64, D16=""), AND(E16<=64, F16=""), AND(G16<=64, H16=""), AND(I16<=64, J16="") ), "", AVERAGE( IF(C16<=64, D16, C16), IF(E16<=64, F16, E16), IF(G16<=64, H16, G16), IF(I16<=64, J16, I16) ) ) | AB16: =IF( OR( D16="", F16="", H16="", J16="", AND(D16<=64, E16=""), AND(F16<=64, G16=""), AND(H16<=64, I16=""), AND(J16<=64, K16="") ), "", AVERAGE( IF(D16<=64, E16, D16), IF(F16<=64, G16, F16), IF(H16<=64, I16, H16), IF(J16<=64, K16, J16) ) ) | AC16: =IF( OR( E16="", G16="", I16="", K16="", AND(E16<=64, F16=""), AND(G16<=64, H16=""), AND(I16<=64, J16=""), AND(K16<=64, L16="") ), "", AVERAGE( IF(E16<=64, F16, E16), IF(G16<=64, H16, G16), IF(I16<=64, J16, I16), IF(K16<=64, L16, K16) ) ) | AD16: =IF(COUNT(AA16, AB16, AC16)<3, "", AVERAGE(AA16, AB16, AC16))
A17: 10 | B17: =Datos!B11 | AA17: =IF( OR( C17="", E17="", G17="", I17="", AND(C17<=64, D17=""), AND(E17<=64, F17=""), AND(G17<=64, H17=""), AND(I17<=64, J17="") ), "", AVERAGE( IF(C17<=64, D17, C17), IF(E17<=64, F17, E17), IF(G17<=64, H17, G17), IF(I17<=64, J17, I17) ) ) | AB17: =IF( OR( D17="", F17="", H17="", J17="", AND(D17<=64, E17=""), AND(F17<=64, G17=""), AND(H17<=64, I17=""), AND(J17<=64, K17="") ), "", AVERAGE( IF(D17<=64, E17, D17), IF(F17<=64, G17, F17), IF(H17<=64, I17, H17), IF(J17<=64, K17, J17) ) ) | AC17: =IF( OR( E17="", G17="", I17="", K17="", AND(E17<=64, F17=""), AND(G17<=64, H17=""), AND(I17<=64, J17=""), AND(K17<=64, L17="") ), "", AVERAGE( IF(E17<=64, F17, E17), IF(G17<=64, H17, G17), IF(I17<=64, J17, I17), IF(K17<=64, L17, K17) ) ) | AD17: =IF(COUNT(AA17, AB17, AC17)<3, "", AVERAGE(AA17, AB17, AC17))
A18: 11 | B18: =Datos!B12 | AA18: =IF( OR( C18="", E18="", G18="", I18="", AND(C18<=64, D18=""), AND(E18<=64, F18=""), AND(G18<=64, H18=""), AND(I18<=64, J18="") ), "", AVERAGE( IF(C18<=64, D18, C18), IF(E18<=64, F18, E18), IF(G18<=64, H18, G18), IF(I18<=64, J18, I18) ) ) | AB18: =IF( OR( D18="", F18="", H18="", J18="", AND(D18<=64, E18=""), AND(F18<=64, G18=""), AND(H18<=64, I18=""), AND(J18<=64, K18="") ), "", AVERAGE( IF(D18<=64, E18, D18), IF(F18<=64, G18, F18), IF(H18<=64, I18, H18), IF(J18<=64, K18, J18) ) ) | AC18: =IF( OR( E18="", G18="", I18="", K18="", AND(E18<=64, F18=""), AND(G18<=64, H18=""), AND(I18<=64, J18=""), AND(K18<=64, L18="") ), "", AVERAGE( IF(E18<=64, F18, E18), IF(G18<=64, H18, G18), IF(I18<=64, J18, I18), IF(K18<=64, L18, K18) ) ) | AD18: =IF(COUNT(AA18, AB18, AC18)<3, "", AVERAGE(AA18, AB18, AC18))
A19: 12 | B19: =Datos!B13 | AA19: =IF( OR( C19="", E19="", G19="", I19="", AND(C19<=64, D19=""), AND(E19<=64, F19=""), AND(G19<=64, H19=""), AND(I19<=64, J19="") ), "", AVERAGE( IF(C19<=64, D19, C19), IF(E19<=64, F19, E19), IF(G19<=64, H19, G19), IF(I19<=64, J19, I19) ) ) | AB19: =IF( OR( D19="", F19="", H19="", J19="", AND(D19<=64, E19=""), AND(F19<=64, G19=""), AND(H19<=64, I19=""), AND(J19<=64, K19="") ), "", AVERAGE( IF(D19<=64, E19, D19), IF(F19<=64, G19, F19), IF(H19<=64, I19, H19), IF(J19<=64, K19, J19) ) ) | AC19: =IF( OR( E19="", G19="", I19="", K19="", AND(E19<=64, F19=""), AND(G19<=64, H19=""), AND(I19<=64, J19=""), AND(K19<=64, L19="") ), "", AVERAGE( IF(E19<=64, F19, E19), IF(G19<=64, H19, G19), IF(I19<=64, J19, I19), IF(K19<=64, L19, K19) ) ) | AD19: =IF(COUNT(AA19, AB19, AC19)<3, "", AVERAGE(AA19, AB19, AC19))
